Workbook
Name Type: 'Working Infos'!$A$1:$A$9

Sheet Working Infos
A1: Working Info | C1: Hour | D1: Minutes
D2: -1
A3: Worked | C3: 0 | D3: 0
A4: Off Day (Overtime Used) | C4: 0.020833333 | D4: 30
A5: Shutdown | C5: 0.041666667 | D5: 60
A6: Holiday | C6: 0.0625 | D6: 90
A7: Sick Day | C7: 0.083333333 | D7: 120
A8: Vacation | C8: 0.10416667 | D8: 150
A9: Work from home | C9: 0.125 | D9: 180
C10: 0.14583333 | D10: 210
C11: 0.16666667 | D11: 240
A12: Payroll Date | C12: 0.1875 | D12: 270
A13: 44925 | C13: 0.20833333 | D13: 300
A14: 44939 | C14: 0.22916667 | D14: 330
A15: 44953 | C15: 0.25 | D15: 360
A16: 44967 | C16: 0.27083333 | D16: 390
A17: 44981 | C17: 0.29166667 | D17: 420
A18: 44995 | C18: 0.3125 | D18: 450
A19: 45009 | C19: 0.33333333 | D19: 480
A20: 45023 | C20: 0.35416667 | D20: 510
A21: 45037 | C21: 0.375 | D21: 540
A22: 45051 | C22: 0.39583333 | D22: 570
A23: 45065 | C23: 0.41666667 | D23: 600
A24: 45079 | C24: 0.4375 | D24: 630
... A50: 45443 | C50: 0.97916667 | D50: 1410
A51: 45457 | C51: +00:00 AM | D51: 1440
A52: 45471 | C52: +00:30 AM | D52: 1470
A53: 45485 | C53: +01:00 AM | D53: 1500
A54: 45499 | C54: +01:30 AM | D54: 1530
A55: 45513 | C55: +02:00 AM | D55: 1560
A56: 45527 | C56: +02:30 AM | D56: 1590
A57: 45541 | C57: +03:00 AM | D57: 1620
A58: 45555 | C58: +03:30 AM | D58: 1650
A59: 45569 | C59: +04:00 AM | D59: 1680
A60: 45583 | C60: +04:30 AM | D60: 1710
A61: 45597 | C61: +05:00 AM | D61: 1740
A62: 45611 | C62: +05:30 AM | D62: 1770
... A77: 45821 | C77: +13:00 AM | D77: 2220
A78: 45835
A79: 45849
...

Sheet Holiday Dates
A1: Date | B1: Holiday
A2: 46023 | B2: New Year's Day
A3: 46024 | B3: Floating Holiday
A4: 46069 | B4: Presidents Day
A5: 46167 | B5: Memorial Day
A6: 46206 | B6: Observed Independence Day
A7: 46272 | B7: Labor Day
A8: 46352 | B8: Thanksgiving Day
A9: 46353 | B9: Floating Holiday
A10: 46381 | B10: Christmas Day

Sheet Timesheet
A1: C&D Semiconductor Services, Inc.
A3: TIME SHEET FOR SALARIED EXEMPT EMPLOYEES
C5: Instructions: Please fill each day with either "Worked", "Sick", "Vacation", "Holiday", or "Shutdown"
C6: Please turn in by the Tuesday before the payroll date.
E8: Employee:
E10: Payroll Date: | I10: {=INDEX(Payrolls[Payroll Date],MATCH(TODAY(),Payrolls[Payroll Date],1)+1)} -> 46297
A12: =_xlfn.ISOWEEKNUM(I10-14) -> 38 | B12: Monday | F12: Tuesday | J12: Wednesday | N12: Thursday | R12: Friday | V12: Saturday | Z12: Sunday
B13: =$I$10-18 -> 46279 | F13: =$I$10-17 -> 46280 | J13: =$I$10-16 -> 46281 | N13: =$I$10-15 -> 46282 | R13: =$I$10-14 -> 46283 | V13: =$I$10-13 -> 46284 | Z13: =$I$10-12 -> 46285
A14: WEEK | B14: =IFERROR(VLOOKUP(B13,'Holiday Dates'!$A$1:$B$100,2,FALSE),"Worked") -> Worked | F14: =IFERROR(VLOOKUP(F13,'Holiday Dates'!$A$1:$B$100,2,FALSE),"Worked") -> Worked | J14: =IFERROR(VLOOKUP(J13,'Holiday Dates'!$A$1:$B$100,2,FALSE),"Worked") -> Worked | N14: =IFERROR(VLOOKUP(N13,'Holiday Dates'!$A$1:$B$100,2,FALSE),"Worked") -> Worked | R14: =IFERROR(VLOOKUP(R13,'Holiday Dates'!$A$1:$B$100,2,FALSE),"Worked") -> Worked
A15: OT
B16: =IF(OR(ISBLANK(B15), ISBLANK(D15)), "", MAX(0, (VLOOKUP(D15,OvertimeData[],2)-VLOOKUP(B15,OvertimeData[],2))/60-8.5)) | F16: =IF(OR(ISBLANK(F15), ISBLANK(H15)), "", MAX(0, (VLOOKUP(H15,OvertimeData[],2)-VLOOKUP(F15,OvertimeData[],2))/60-8.5)) | J16: =IF(OR(ISBLANK(J15), ISBLANK(L15)), "", MAX(0, (VLOOKUP(L15,OvertimeData[],2)-VLOOKUP(J15,OvertimeData[],2))/60-8.5)) | N16: =IF(OR(ISBLANK(N15), ISBLANK(P15)), "", MAX(0, (VLOOKUP(P15,OvertimeData[],2)-VLOOKUP(N15,OvertimeData[],2))/60-8.5)) | R16: =IF(OR(ISBLANK(R15), ISBLANK(T15)), "", MAX(0, (VLOOKUP(T15,OvertimeData[],2)-VLOOKUP(R15,OvertimeData[],2))/60-8.5)) | V16: =IF(OR(ISBLANK(V15), ISBLANK(X15)), "", MAX(0, (VLOOKUP(X15,OvertimeData[],2)-VLOOKUP(V15,OvertimeData[],2))/60-8.5)) | Z16: =IF(OR(ISBLANK(Z15), ISBLANK(AB15)), "", MAX(0, (VLOOKUP(AB15,OvertimeData[],2)-VLOOKUP(Z15,OvertimeData[],2))/60-8.5))
V17: =IF(ISBLANK(V14),"",INDEX(OvertimeData[Hour],MATCH(480,OvertimeData[Minutes], 0))) | Z17: =IF(ISBLANK(Z14),"",INDEX(OvertimeData[Hour],MATCH(480,OvertimeData[Minutes], 0))) | AB17: =IF(ISBLANK(Z14),"",INDEX(OvertimeData[Hour],MATCH(930,OvertimeData[Minutes], 0)))
V18: =IF(ISBLANK(V21),"",INDEX(OvertimeData[Hour],MATCH(480,OvertimeData[Minutes], 0))) | Z18: =IF(ISBLANK(Z21),"",INDEX(OvertimeData[Hour],MATCH(480,OvertimeData[Minutes], 0))) | AB18: =IF(ISBLANK(Z21),"",INDEX(OvertimeData[Hour],MATCH(930,OvertimeData[Minutes], 0)))
A19: =_xlfn.ISOWEEKNUM(I10-7) -> 39 | B19: Monday | F19: Tuesday | J19: Wednesday | N19: Thursday | R19: Friday | V19: Saturday | Z19: Sunday
B20: =$I$10-11 -> 46286 | F20: =$I$10-10 -> 46287 | J20: =$I$10-9 -> 46288 | N20: =$I$10-8 -> 46289 | R20: =$I$10-7 -> 46290 | V20: =$I$10-6 -> 46291 | Z20: =$I$10-5 -> 46292
A21: WEEK | B21: =IFERROR(VLOOKUP(B20,'Holiday Dates'!$A$1:$B$100,2,FALSE),"Worked") -> Worked | F21: =IFERROR(VLOOKUP(F20,'Holiday Dates'!$A$1:$B$100,2,FALSE),"Worked") -> Worked | J21: =IFERROR(VLOOKUP(J20,'Holiday Dates'!$A$1:$B$100,2,FALSE),"Worked") -> Worked | N21: =IFERROR(VLOOKUP(N20,'Holiday Dates'!$A$1:$B$100,2,FALSE),"Worked") -> Worked | R21: Worked
A22: OT
B23: =IF(OR(ISBLANK(B22), ISBLANK(D22)), "", MAX(0, (VLOOKUP(D22,OvertimeData[],2)-VLOOKUP(B22,OvertimeData[],2))/60-8.5)) | F23: =IF(OR(ISBLANK(F22), ISBLANK(H22)), "", MAX(0, (VLOOKUP(H22,OvertimeData[],2)-VLOOKUP(F22,OvertimeData[],2))/60-8.5)) | J23: =IF(OR(ISBLANK(J22), ISBLANK(L22)), "", MAX(0, (VLOOKUP(L22,OvertimeData[],2)-VLOOKUP(J22,OvertimeData[],2))/60-8.5)) | N23: =IF(OR(ISBLANK(N22), ISBLANK(P22)), "", MAX(0, (VLOOKUP(P22,OvertimeData[],2)-VLOOKUP(N22,OvertimeData[],2))/60-8.5)) | R23: =IF(OR(ISBLANK(R22), ISBLANK(T22)), "", MAX(0, (VLOOKUP(T22,OvertimeData[],2)-VLOOKUP(R22,OvertimeData[],2))/60-8.5)) | V23: =IF(OR(ISBLANK(V22), ISBLANK(X22)), "", MAX(0, (VLOOKUP(X22,OvertimeData[],2)-VLOOKUP(V22,OvertimeData[],2))/60-8.5)) | Z23: =IF(OR(ISBLANK(Z22), ISBLANK(AB22)), "", MAX(0, (VLOOKUP(AB22,OvertimeData[],2)-VLOOKUP(Z22,OvertimeData[],2))/60-8.5))
N24: Overtime Total : | X24: =SUM($B$16:$Y$16)+SUM($B$23:$Y$23) -> 0 | Z24: hours
W26: =TODAY() -> 46295
B27: Employee Signature | W27: Date
B30: Manager Signature | W30: Date
